<?xml version="1.0" ?>
<robot name="testarm" xmlns:xacro="http://www.ros.org/wiki/xacro">
      
  
    <xacro:include filename="$(find rover_arm)/urdf/arm.xacro"/>

    <link name="base_cylinder">
      <collision>
        <origin rpy="0 0 0" xyz="0.0 0.0 0.0"/>
        <geometry>
          <cylinder length="0.1" radius="0.5"/>
        </geometry>
      </collision>
      <visual>
        <origin rpy="0 0 0" xyz="0.0 0.0 0.0"/>
        <geometry>
          <cylinder length="0.1" radius="0.5"/>
        </geometry>
        <material name="black"/>
      </visual>
      <inertial>
          <origin rpy="0 0 0" xyz="0 0 0"/>
          <mass value="100"/>
          <cylinder_inertia m="100" r="${0.5}" h="${0.1}" />
      </inertial>
    </link>

    <arm parent="base_cylinder" translateX="0" translateY="0.3" translateZ="0.15"/>
    
    
    
    
    <!--   base link can't have inertia   -->
    <!--   MoveIt needs a fixed world joint   -->
    <link name="world" />

    <joint name="world_joint" type="continuous">
        <parent link="world" />
        <child link = "base_cylinder" />
        <origin xyz="0.0 0.0 0.0" rpy="0.0 0.0 0.0" />
    </joint>

    
    
   <gazebo>
      <plugin name="joint_state_publisher" filename="libgazebo_ros_joint_state_publisher.so">
         <jointName>
<!--             world_joint, -->
            joint0, 
            joint1, 
            joint2,
            joint3,
            joint4,
            joint_hand
         </jointName>
         <robotNameSpace>/</robotNameSpace>
         <updateRate>100</updateRate>
         <alwaysOn>true</alwaysOn>
      </plugin>
   </gazebo>

   <!-- <gazebo>
      <plugin name="gazebo_ros_control" filename="libgazebo_ros_control.so">
         <robotNamespace>/</robotNamespace>
         <robotSimType>gazebo_ros_control/DefaultRobotHWSim</robotSimType>
         <legacyModeNS>true</legacyModeNS>
      </plugin>
   </gazebo> -->

    <gazebo>
        <plugin name="gazebo_ros_control" filename="libgazebo_ros_control.so">
<!--             <robotNamespace>/nimrod</robotNamespace> -->
        </plugin>
    </gazebo>

</robot>
